Workbook

Sheet 🏠 Cover
B2: VIRORAH PMS
B3: Enterprise OKR Execution Toolkit
B4: Hybrid Google · SMART Scoring · 4-Level Cascade · Stretch vs Committed · Cross-Functional Dependencies
B7: WHAT'S IN THIS WORKBOOK
B8: 🏠 Cover | F8: This page — navigation and instructions
B9: ⚙️ Config | F9: Org settings, scoring method, quarter dates, owners
B10: 🏢 L1 Company OKRs | F10: Top-level company objectives (CEO / Board)
B11: 🏬 L2 Dept OKRs | F11: Department-level OKRs linked to Company objectives
B12: 👥 L3 Team OKRs | F12: Team-level OKRs linked to Department objectives
B13: 👤 L4 Individual | F13: Individual KRs linked to Team objectives
B14: 📊 Cascade View | F14: Full cascade in one view — Company → Dept → Team → Individual
B15: 🌡️ Health Dashboard | F15: CHRO-level OKR health across the entire org
B16: 📅 Check-in Log | F16: Weekly confidence updates with trend tracking
B17: ⚡ Stretch vs Commit | F17: Aspirational vs committed OKR split tracker
B18: 🔗 Dependencies | F18: Cross-functional dependency mapping
B19: 📖 Scoring Guide | F19: How to score OKRs — Google model + SMART model explained
B22: COLOR CODE
B23: ● | C23: Blue text = User input cells — fill these in
B24: ● | C24: Green text = Formula cells — do not edit
B25: ● | C25: 🟢 Green score/badge = On Track (≥ 0.7 / ≥ 70%)
B26: ● | C26: 🟡 Amber score/badge = At Risk (0.4–0.69 / 40–69%)
B27: ● | C27: 🔴 Red score/badge = Off Track (< 0.4 / < 40%)
B28: ● | C28: Purple = Section headers / Virorah brand

Sheet ⚙️ Config
B1: ⚙️ ORG CONFIGURATION
B2: Enter your org details here. These values are referenced across all sheets.
B3: ORG SETTINGS
B4: Organisation Name | C4: Virorah Private Limited
B5: OKR Period (Quarter) | C5: Q3 2026
B6: Period Start Date | C6: 01 Jul 2026
B7: Period End Date | C7: 30 Sep 2026
B8: Total Headcount | C8: 50
B9: CEO / Top Executive | C9: Vivek Kumar
B11: SCORING METHOD
B12: Primary Scoring Method | C12: Google (0.0–1.0)
B13: Google: Target Score (aspirational) | C13: 0.7
B14: Google: Committed floor | C14: 1
B15: SMART: Target = 100%
B17: OKR COVERAGE TARGET
B18: % of org with OKRs set | C18: 80%
B19: Levels covered | C19: Company, Dept, Team, Individual
B20: Max KRs per Objective | C20: 4
B22: RATING LABELS
B23: Score 0.9–1.0 | C23: 🏆 Supercharged
B24: Score 0.7–0.89 | C24: 🟢 On Track
B25: Score 0.4–0.69 | C25: 🟡 At Risk
B26: Score 0.0–0.39 | C26: 🔴 Off Track
B28: OWNERS (auto-populate dropdowns)
B29: Owner 1 | C29: CEO
B30: Owner 2 | C30: CHRO
B31: Owner 3 | C31: CPO
B32: Owner 4 | C32: CTO
B33: Owner 5 | C33: CMO
B34: Owner 6 | C34: CFO
B35: Owner 7 | C35: Head of Engineering
B36: Owner 8 | C36: Head of Growth
B37: Owner 9 | C37: Head of Product
B38: Owner 10 | C38: Head of HR

Sheet 🏢 L1 Company OKRs
B1: 🏢 COMPANY OKRs · Level 1
B2: Blue cells = your inputs · Green cells = auto-calculated · Update "Current" columns weekly · Linked to ⚙️ Config
F3: GOOGLE OKR SCORING (0.0 – 1.0) | L3: SMART SCORING (%) | O3: STATUS & METADATA
B4: # | C4: OBJ # | D4: Objective | E4: Key Result | F4: Owner / DRI | G4: KR Type | H4: Baseline | I4: Stretch Target | J4: Current | K4: KR Score (0–1) | L4: Obj Score (0–1) | M4: Target (100%) | N4: Actual (%) | O4: SMART Score | P4: Confidence Level | Q4: Check-in Date | R4: Period | S4: Linked to Board / Vision | T4: Stretch vs Commit | U4: Dependencies | V4: Notes
B5: 1 | C5: Establish Virorah PMS as the #1 HR EdTech platform in India by end of 2026 | D5: Reach 10,000 active Pro subscribers globally | E5: CEO | F5: Aspirational | G5: 0 | H5: 10000 | I5: 340 | J5: =IFERROR(IF(H5=G5,IF(I5>=H5,1,0),(I5-G5)/(H5-G5)),0) -> 0.034 | K5: =IFERROR(AVERAGEIF(C5:C200,C5,J5:J200),"") -> 0.034 | L5: 100 | M5: =IFERROR(IF(H5=G5,IF(I5>=H5,100,0),(I5-G5)/(H5-G5)*100),0) -> 3.4 | N5: =IF(M5="","",IF(M5>=90,"🏆 Supercharged",IF(M5>=70,"🟢 On Track",IF(M5>=40,"🟡 At Risk","🔴 Off Track")))) -> 🔴 Off Track | O5: High | Q5: ='⚙️ Config'!C5 -> Q3 2026 | R5: Board OKR | S5: Stretch | T5: Gumroad + Razorpay payment activation | U5: Primary growth KR
B6: 2 | D6: Achieve Net Promoter Score of 65+ from Pro users | E6: CPO | F6: Committed | G6: 0 | H6: 65 | I6: 0 | J6: =IFERROR(IF(H6=G6,IF(I6>=H6,1,0),(I6-G6)/(H6-G6)),0) -> 0 | K6: =IFERROR(AVERAGEIF(C5:C200,C6,J5:J200),"") | L6: 100 | M6: =IFERROR(IF(H6=G6,IF(I6>=H6,100,0),(I6-G6)/(H6-G6)*100),0) -> 0 | N6: =IF(M6="","",IF(M6>=90,"🏆 Supercharged",IF(M6>=70,"🟢 On Track",IF(M6>=40,"🟡 At Risk","🔴 Off Track")))) -> 🔴 Off Track | O6: Medium | Q6: ='⚙️ Config'!C5 -> Q3 2026 | R6: Board OKR | S6: Commit | T6: User survey tool setup | U6: First survey at 500 users
B7: 3 | D7: Launch in 3 international markets (SG, UAE, UK) | E7: CMO | F7: Aspirational | G7: 0 | H7: 3 | I7: 0 | J7: =IFERROR(IF(H7=G7,IF(I7>=H7,1,0),(I7-G7)/(H7-G7)),0) -> 0 | K7: =IFERROR(AVERAGEIF(C5:C200,C7,J5:J200),"") | L7: 100 | M7: =IFERROR(IF(H7=G7,IF(I7>=H7,100,0),(I7-G7)/(H7-G7)*100),0) -> 0 | N7: =IF(M7="","",IF(M7>=90,"🏆 Supercharged",IF(M7>=70,"🟢 On Track",IF(M7>=40,"🟡 At Risk","🔴 Off Track")))) -> 🔴 Off Track | O7: Low | Q7: ='⚙️ Config'!C5 -> Q3 2026 | R7: Board OKR | S7: Stretch | T7: Gumroad international payments | U7: Gumroad live = auto-unlock
B8: 4 | D8: Secure DPIIT Startup India recognition | E8: CFO | F8: Committed | G8: 0 | H8: 1 | I8: 0 | J8: =IFERROR(IF(H8=G8,IF(I8>=H8,1,0),(I8-G8)/(H8-G8)),0) -> 0 | K8: =IFERROR(AVERAGEIF(C5:C200,C8,J5:J200),"") | L8: 100 | M8: =IFERROR(IF(H8=G8,IF(I8>=H8,100,0),(I8-G8)/(H8-G8)*100),0) -> 0 | N8: =IF(M8="","",IF(M8>=90,"🏆 Supercharged",IF(M8>=70,"🟢 On Track",IF(M8>=40,"🟡 At Risk","🔴 Off Track")))) -> 🔴 Off Track | O8: High | Q8: ='⚙️ Config'!C5 -> Q3 2026 | R8: Board OKR | S8: Commit | T8: INC 20A filing completion | U8: CA handling
B9: 5 | C9: Build a product that genuinely replaces enterprise PMS tools at 5% of their cost | D9: Ship Goal Diagnostic Lab + Bias Audit to 100% of Pro users | E9: CPO | F9: Committed | G9: 0 | H9: 1 | I9: 1 | J9: =IFERROR(IF(H9=G9,IF(I9>=H9,1,0),(I9-G9)/(H9-G9)),0) -> 1 | K9: =IFERROR(AVERAGEIF(C5:C200,C9,J5:J200),"") -> 1 | L9: 100 | M9: =IFERROR(IF(H9=G9,IF(I9>=H9,100,0),(I9-G9)/(H9-G9)*100),0) -> 100 | N9: =IF(M9="","",IF(M9>=90,"🏆 Supercharged",IF(M9>=70,"🟢 On Track",IF(M9>=40,"🟡 At Risk","🔴 Off Track")))) -> 🏆 Supercharged | O9: High | Q9: ='⚙️ Config'!C5 -> Q3 2026 | R9: Board OKR | S9: Commit | T9: None | U9: Completed ✅
B10: 6 | D10: Deliver 3 enterprise-grade Excel toolkits in Downloads Library | E10: CPO | F10: Committed | G10: 0 | H10: 3 | I10: 3 | J10: =IFERROR(IF(H10=G10,IF(I10>=H10,1,0),(I10-G10)/(H10-G10)),0) -> 1 | K10: =IFERROR(AVERAGEIF(C5:C200,C10,J5:J200),"") | L10: 100 | M10: =IFERROR(IF(H10=G10,IF(I10>=H10,100,0),(I10-G10)/(H10-G10)*100),0) -> 100 | N10: =IF(M10="","",IF(M10>=90,"🏆 Supercharged",IF(M10>=70,"🟢 On Track",IF(M10>=40,"🟡 At Risk","🔴 Off Track")))) -> 🏆 Supercharged | O10: High | Q10: ='⚙️ Config'!C5 -> Q3 2026 | R10: Board OKR | S10: Commit | T10: None | U10: Completed ✅
B11: 7 | D11: Achieve < 3 min time-to-first-insight from sign-up | E11: CTO | F11: Aspirational | G11: 0 | H11: 3 | I11: 0 | J11: =IFERROR(IF(H11=G11,IF(I11>=H11,1,0),(I11-G11)/(H11-G11)),0) -> 0 | K11: =IFERROR(AVERAGEIF(C5:C200,C11,J5:J200),"") | L11: 100 | M11: =IFERROR(IF(H11=G11,IF(I11>=H11,100,0),(I11-G11)/(H11-G11)*100),0) -> 0 | N11: =IF(M11="","",IF(M11>=90,"🏆 Supercharged",IF(M11>=70,"🟢 On Track",IF(M11>=40,"🟡 At Risk","🔴 Off Track")))) -> 🔴 Off Track | O11: Medium | Q11: ='⚙️ Config'!C5 -> Q3 2026 | R11: Board OKR | S11: Stretch | T11: Onboarding flow design | U11: Track via GA4
B12: 8 | D12: Launch 4 Pro certifications with unique credential IDs | E12: CPO | F12: Committed | G12: 0 | H12: 4 | I12: 4 | J12: =IFERROR(IF(H12=G12,IF(I12>=H12,1,0),(I12-G12)/(H12-G12)),0) -> 1 | K12: =IFERROR(AVERAGEIF(C5:C200,C12,J5:J200),"") | L12: 100 | M12: =IFERROR(IF(H12=G12,IF(I12>=H12,100,0),(I12-G12)/(H12-G12)*100),0) -> 100 | N12: =IF(M12="","",IF(M12>=90,"🏆 Supercharged",IF(M12>=70,"🟢 On Track",IF(M12>=40,"🟡 At Risk","🔴 Off Track")))) -> 🏆 Supercharged | O12: High | Q12: ='⚙️ Config'!C5 -> Q3 2026 | R12: Board OKR | S12: Commit | T12: None | U12: All 4 live
B13: 9 | C13: Achieve financial sustainability within 12 months of launch | D13: Hit ₹50L ARR by end of FY2026 | E13: CEO | F13: Aspirational | G13: 0 | H13: 5000000 | I13: 0 | J13: =IFERROR(IF(H13=G13,IF(I13>=H13,1,0),(I13-G13)/(H13-G13)),0) -> 0 | K13: =IFERROR(AVERAGEIF(C5:C200,C13,J5:J200),"") -> 0 | L13: 100 | M13: =IFERROR(IF(H13=G13,IF(I13>=H13,100,0),(I13-G13)/(H13-G13)*100),0) -> 0 | N13: =IF(M13="","",IF(M13>=90,"🏆 Supercharged",IF(M13>=70,"🟢 On Track",IF(M13>=40,"🟡 At Risk","🔴 Off Track")))) -> 🔴 Off Track | O13: Low | Q13: ='⚙️ Config'!C5 -> Q3 2026 | R13: Board OKR | S13: Stretch | T13: Payment stack live | U13: Gumroad + Razorpay needed
B14: 10 | D14: Keep monthly burn below ₹8L | E14: CFO | F14: Committed | G14: 0 | H14: 800000 | I14: 0 | J14: =IFERROR(IF(H14=G14,IF(I14>=H14,1,0),(I14-G14)/(H14-G14)),0) -> 0 | K14: =IFERROR(AVERAGEIF(C5:C200,C14,J5:J200),"") | L14: 100 | M14: =IFERROR(IF(H14=G14,IF(I14>=H14,100,0),(I14-G14)/(H14-G14)*100),0) -> 0 | N14: =IF(M14="","",IF(M14>=90,"🏆 Supercharged",IF(M14>=70,"🟢 On Track",IF(M14>=40,"🟡 At Risk","🔴 Off Track")))) -> 🔴 Off Track | O14: High | Q14: ='⚙️ Config'!C5 -> Q3 2026 | R14: Board OKR | S14: Commit | T14: None | U14: Track monthly
B15: 11 | D15: Achieve 40% gross margin on Pro subscriptions | E15: CFO | F15: Aspirational | G15: 0 | H15: 40 | I15: 0 | J15: =IFERROR(IF(H15=G15,IF(I15>=H15,1,0),(I15-G15)/(H15-G15)),0) -> 0 | K15: =IFERROR(AVERAGEIF(C5:C200,C15,J5:J200),"") | L15: 100 | M15: =IFERROR(IF(H15=G15,IF(I15>=H15,100,0),(I15-G15)/(H15-G15)*100),0) -> 0 | N15: =IF(M15="","",IF(M15>=90,"🏆 Supercharged",IF(M15>=70,"🟢 On Track",IF(M15>=40,"🟡 At Risk","🔴 Off Track")))) -> 🔴 Off Track | O15: Medium | Q15: ='⚙️ Config'!C5 -> Q3 2026 | R15: Board OKR | S15: Stretch | T15: Pricing model finalised | U15: After 500 paying users
B17: PERIOD SUMMARY | F17: Avg Google Score | G17: =IFERROR(AVERAGE(J5:J15),"—") -> 0.27581818 | H17: Avg SMART % | I17: =IFERROR(AVERAGE(M5:M15),"—") -> 27.581818 | J17: On Track KRs | K17: =COUNTIF(J5:J15,">=0.7") -> 3 | L17: At Risk KRs | M17: =COUNTIFS(J5:J15,">=0.4",J5:J15,"<0.7") -> 0 | N17: Off Track KRs | O17: =COUNTIF(J5:J15,"<0.4") -> 8

Sheet 🏬 L2 Dept OKRs
B1: 🏬 DEPARTMENT OKRs · Level 2
B2: Blue cells = your inputs · Green cells = auto-calculated · Update "Current" columns weekly · Linked to ⚙️ Config
F3: GOOGLE OKR SCORING (0.0 – 1.0) | L3: SMART SCORING (%) | O3: STATUS & METADATA
B4: # | C4: OBJ # | D4: Objective | E4: Key Result | F4: Owner / DRI | G4: KR Type | H4: Baseline | I4: Stretch Target | J4: Current | K4: KR Score (0–1) | L4: Obj Score (0–1) | M4: Target (100%) | N4: Actual (%) | O4: SMART Score | P4: Confidence Level | Q4: Check-in Date | R4: Period | S4: Linked to Company OKR | T4: Stretch vs Commit | U4: Dependencies | V4: Notes
B5: 1 | C5: Product: Deliver a 10/10 learning experience that HR professionals recommend unprompted | D5: Reduce page load time to < 2s on all calculator pages | E5: Head of Engineering | F5: Committed | G5: 0 | H5: 2 | I5: 0 | J5: =IFERROR(IF(H5=G5,IF(I5>=H5,1,0),(I5-G5)/(H5-G5)),0) -> 0 | K5: =IFERROR(AVERAGEIF(C5:C200,C5,J5:J200),"") -> 0 | L5: 100 | M5: =IFERROR(IF(H5=G5,IF(I5>=H5,100,0),(I5-G5)/(H5-G5)*100),0) -> 0 | N5: =IF(M5="","",IF(M5>=90,"🏆 Supercharged",IF(M5>=70,"🟢 On Track",IF(M5>=40,"🟡 At Risk","🔴 Off Track")))) -> 🔴 Off Track | O5: Medium | Q5: ='⚙️ Config'!C5 -> Q3 2026 | R5: Establish as #1 platform | S5: Commit | T5: CDN / caching setup | U5: Measure via Lighthouse
B6: 2 | D6: Ship Conversation Simulator v2 with lip-sync | E6: Head of Product | F6: Aspirational | G6: 3 | H6: 5 | I6: 3 | J6: =IFERROR(IF(H6=G6,IF(I6>=H6,1,0),(I6-G6)/(H6-G6)),0) -> 0 | K6: =IFERROR(AVERAGEIF(C5:C200,C6,J5:J200),"") | L6: 100 | M6: =IFERROR(IF(H6=G6,IF(I6>=H6,100,0),(I6-G6)/(H6-G6)*100),0) -> 0 | N6: =IF(M6="","",IF(M6>=90,"🏆 Supercharged",IF(M6>=70,"🟢 On Track",IF(M6>=40,"🟡 At Risk","🔴 Off Track")))) -> 🔴 Off Track | O6: Low | Q6: ='⚙️ Config'!C5 -> Q3 2026 | R6: Build product replacing enterprise tools | S6: Stretch | T6: D-ID API integration (post-revenue) | U6: CSS lip overlay abandoned — real lip-sync needed
B7: 3 | D7: Publish 20 expert guides in Learning Hub | E7: Head of Product | F7: Committed | G7: 0 | H7: 20 | I7: 14 | J7: =IFERROR(IF(H7=G7,IF(I7>=H7,1,0),(I7-G7)/(H7-G7)),0) -> 0.7 | K7: =IFERROR(AVERAGEIF(C5:C200,C7,J5:J200),"") | L7: 100 | M7: =IFERROR(IF(H7=G7,IF(I7>=H7,100,0),(I7-G7)/(H7-G7)*100),0) -> 70 | N7: =IF(M7="","",IF(M7>=90,"🏆 Supercharged",IF(M7>=70,"🟢 On Track",IF(M7>=40,"🟡 At Risk","🔴 Off Track")))) -> 🟢 On Track | O7: High | Q7: ='⚙️ Config'!C5 -> Q3 2026 | R7: Build product replacing enterprise tools | S7: Commit | T7: None | U7: 14 live, 6 remaining
B8: 4 | D8: Achieve 4.5+ star avg on tool quality rating | E8: CPO | F8: Aspirational | G8: 0 | H8: 4.5 | I8: 0 | J8: =IFERROR(IF(H8=G8,IF(I8>=H8,1,0),(I8-G8)/(H8-G8)),0) -> 0 | K8: =IFERROR(AVERAGEIF(C5:C200,C8,J5:J200),"") | L8: 100 | M8: =IFERROR(IF(H8=G8,IF(I8>=H8,100,0),(I8-G8)/(H8-G8)*100),0) -> 0 | N8: =IF(M8="","",IF(M8>=90,"🏆 Supercharged",IF(M8>=70,"🟢 On Track",IF(M8>=40,"🟡 At Risk","🔴 Off Track")))) -> 🔴 Off Track | O8: Medium | Q8: ='⚙️ Config'!C5 -> Q3 2026 | R8: Build product replacing enterprise tools | S8: Stretch | T8: In-app rating widget | U8: After beta launch
B9: 5 | C9: Growth: Build a repeatable acquisition engine for HR professionals | D9: Launch 15-post LinkedIn campaign on Day 1 of Gumroad activation | E9: CMO | F9: Committed | G9: 0 | H9: 15 | I9: 0 | J9: =IFERROR(IF(H9=G9,IF(I9>=H9,1,0),(I9-G9)/(H9-G9)),0) -> 0 | K9: =IFERROR(AVERAGEIF(C5:C200,C9,J5:J200),"") -> 0 | L9: 100 | M9: =IFERROR(IF(H9=G9,IF(I9>=H9,100,0),(I9-G9)/(H9-G9)*100),0) -> 0 | N9: =IF(M9="","",IF(M9>=90,"🏆 Supercharged",IF(M9>=70,"🟢 On Track",IF(M9>=40,"🟡 At Risk","🔴 Off Track")))) -> 🔴 Off Track | O9: High | Q9: ='⚙️ Config'!C5 -> Q3 2026 | R9: Reach 10k subscribers | S9: Commit | T9: Gumroad payment links live | U9: Campaign written, not launched
B10: 6 | D10: Achieve 500 email signups in first 30 days post-launch | E10: CMO | F10: Aspirational | G10: 0 | H10: 500 | I10: 0 | J10: =IFERROR(IF(H10=G10,IF(I10>=H10,1,0),(I10-G10)/(H10-G10)),0) -> 0 | K10: =IFERROR(AVERAGEIF(C5:C200,C10,J5:J200),"") | L10: 100 | M10: =IFERROR(IF(H10=G10,IF(I10>=H10,100,0),(I10-G10)/(H10-G10)*100),0) -> 0 | N10: =IF(M10="","",IF(M10>=90,"🏆 Supercharged",IF(M10>=70,"🟢 On Track",IF(M10>=40,"🟡 At Risk","🔴 Off Track")))) -> 🔴 Off Track | O10: Medium | Q10: ='⚙️ Config'!C5 -> Q3 2026 | R10: Reach 10k subscribers | S10: Stretch | T10: Resend email integration | U10: After payments live
B11: 7 | D11: Get featured in 3 HR newsletters or communities | E11: CMO | F11: Aspirational | G11: 0 | H11: 3 | I11: 0 | J11: =IFERROR(IF(H11=G11,IF(I11>=H11,1,0),(I11-G11)/(H11-G11)),0) -> 0 | K11: =IFERROR(AVERAGEIF(C5:C200,C11,J5:J200),"") | L11: 100 | M11: =IFERROR(IF(H11=G11,IF(I11>=H11,100,0),(I11-G11)/(H11-G11)*100),0) -> 0 | N11: =IF(M11="","",IF(M11>=90,"🏆 Supercharged",IF(M11>=70,"🟢 On Track",IF(M11>=40,"🟡 At Risk","🔴 Off Track")))) -> 🔴 Off Track | O11: Low | Q11: ='⚙️ Config'!C5 -> Q3 2026 | R11: Reach 10k subscribers | S11: Stretch | T11: Outreach list | U11: Identify top 10 HR newsletters
B12: 8 | D12: Convert 10% of free users to Pro within 60 days | E12: CMO | F12: Aspirational | G12: 0 | H12: 10 | I12: 0 | J12: =IFERROR(IF(H12=G12,IF(I12>=H12,1,0),(I12-G12)/(H12-G12)),0) -> 0 | K12: =IFERROR(AVERAGEIF(C5:C200,C12,J5:J200),"") | L12: 100 | M12: =IFERROR(IF(H12=G12,IF(I12>=H12,100,0),(I12-G12)/(H12-G12)*100),0) -> 0 | N12: =IF(M12="","",IF(M12>=90,"🏆 Supercharged",IF(M12>=70,"🟢 On Track",IF(M12>=40,"🟡 At Risk","🔴 Off Track")))) -> 🔴 Off Track | O12: Medium | Q12: ='⚙️ Config'!C5 -> Q3 2026 | R12: Reach 10k subscribers | S12: Stretch | T12: Conversion funnel tracking | U12: GA4 goal setup needed
B13: 9 | C13: People & Culture: Build a culture of learning and radical transparency | D13: Complete all-hands OKR review every 2 weeks | E13: CHRO | F13: Committed | G13: 0 | H13: 6 | I13: 0 | J13: =IFERROR(IF(H13=G13,IF(I13>=H13,1,0),(I13-G13)/(H13-G13)),0) -> 0 | K13: =IFERROR(AVERAGEIF(C5:C200,C13,J5:J200),"") -> 0 | L13: 100 | M13: =IFERROR(IF(H13=G13,IF(I13>=H13,100,0),(I13-G13)/(H13-G13)*100),0) -> 0 | N13: =IF(M13="","",IF(M13>=90,"🏆 Supercharged",IF(M13>=70,"🟢 On Track",IF(M13>=40,"🟡 At Risk","🔴 Off Track")))) -> 🔴 Off Track | O13: High | Q13: ='⚙️ Config'!C5 -> Q3 2026 | R13: Financial sustainability | S13: Commit | T13: None | U13: 6 bi-weekly sessions per quarter
B14: 10 | D14: 100% of team has individual OKRs linked to company objectives | E14: CHRO | F14: Committed | G14: 0 | H14: 100 | I14: 60 | J14: =IFERROR(IF(H14=G14,IF(I14>=H14,1,0),(I14-G14)/(H14-G14)),0) -> 0.6 | K14: =IFERROR(AVERAGEIF(C5:C200,C14,J5:J200),"") | L14: 100 | M14: =IFERROR(IF(H14=G14,IF(I14>=H14,100,0),(I14-G14)/(H14-G14)*100),0) -> 60 | N14: =IF(M14="","",IF(M14>=90,"🏆 Supercharged",IF(M14>=70,"🟢 On Track",IF(M14>=40,"🟡 At Risk","🔴 Off Track")))) -> 🟡 At Risk | O14: High | Q14: ='⚙️ Config'!C5 -> Q3 2026 | R14: All company OKRs | S14: Commit | T14: None | U14: 60% done — L4 sheet in progress
B15: 11 | D15: Implement anonymous pulse survey with > 80% participation | E15: CHRO | F15: Aspirational | G15: 0 | H15: 80 | I15: 0 | J15: =IFERROR(IF(H15=G15,IF(I15>=H15,1,0),(I15-G15)/(H15-G15)),0) -> 0 | K15: =IFERROR(AVERAGEIF(C5:C200,C15,J5:J200),"") | L15: 100 | M15: =IFERROR(IF(H15=G15,IF(I15>=H15,100,0),(I15-G15)/(H15-G15)*100),0) -> 0 | N15: =IF(M15="","",IF(M15>=90,"🏆 Supercharged",IF(M15>=70,"🟢 On Track",IF(M15>=40,"🟡 At Risk","🔴 Off Track")))) -> 🔴 Off Track | O15: Low | Q15: ='⚙️ Config'!C5 -> Q3 2026 | R15: Build 10/10 experience | S15: Stretch | T15: Survey tool | U15: Post-launch priority
B17: PERIOD SUMMARY | F17: Avg Google Score | G17: =IFERROR(AVERAGE(J5:J15),"—") -> 0.11818182 | H17: Avg SMART % | I17: =IFERROR(AVERAGE(M5:M15),"—") -> 11.818182 | J17: On Track KRs | K17: =COUNTIF(J5:J15,">=0.7") -> 1 | L17: At Risk KRs | M17: =COUNTIFS(J5:J15,">=0.4",J5:J15,"<0.7") -> 1 | N17: Off Track KRs | O17: =COUNTIF(J5:J15,"<0.4") -> 9

Sheet 👥 L3 Team OKRs
B1: 👥 TEAM OKRs · Level 3
B2: Blue cells = your inputs · Green cells = auto-calculated · Update "Current" columns weekly · Linked to ⚙️ Config
F3: GOOGLE OKR SCORING (0.0 – 1.0) | L3: SMART SCORING (%) | O3: STATUS & METADATA
B4: # | C4: OBJ # | D4: Objective | E4: Key Result | F4: Owner / DRI | G4: KR Type | H4: Baseline | I4: Stretch Target | J4: Current | K4: KR Score (0–1) | L4: Obj Score (0–1) | M4: Target (100%) | N4: Actual (%) | O4: SMART Score | P4: Confidence Level | Q4: Check-in Date | R4: Period | S4: Linked to Dept OKR | T4: Stretch vs Commit | U4: Dependencies | V4: Notes
B5: 1 | C5: Engineering: Ship reliable, fast, delightful platform features every sprint | D5: Zero critical bugs in production for 30 consecutive days | E5: Tech Lead | F5: Committed | G5: 0 | H5: 30 | I5: 0 | J5: =IFERROR(IF(H5=G5,IF(I5>=H5,1,0),(I5-G5)/(H5-G5)),0) -> 0 | K5: =IFERROR(AVERAGEIF(C5:C200,C5,J5:J200),"") -> 0 | L5: 100 | M5: =IFERROR(IF(H5=G5,IF(I5>=H5,100,0),(I5-G5)/(H5-G5)*100),0) -> 0 | N5: =IF(M5="","",IF(M5>=90,"🏆 Supercharged",IF(M5>=70,"🟢 On Track",IF(M5>=40,"🟡 At Risk","🔴 Off Track")))) -> 🔴 Off Track | O5: Medium | Q5: ='⚙️ Config'!C5 -> Q3 2026 | R5: Product delivers 10/10 experience | S5: Commit | T5: QA process setup | U5: Track on Notion
B6: 2 | D6: Deploy PDF export to Goal Lab + Bias Audit | E6: Tech Lead | F6: Committed | G6: 0 | H6: 1 | I6: 1 | J6: =IFERROR(IF(H6=G6,IF(I6>=H6,1,0),(I6-G6)/(H6-G6)),0) -> 1 | K6: =IFERROR(AVERAGEIF(C5:C200,C6,J5:J200),"") | L6: 100 | M6: =IFERROR(IF(H6=G6,IF(I6>=H6,100,0),(I6-G6)/(H6-G6)*100),0) -> 100 | N6: =IF(M6="","",IF(M6>=90,"🏆 Supercharged",IF(M6>=70,"🟢 On Track",IF(M6>=40,"🟡 At Risk","🔴 Off Track")))) -> 🏆 Supercharged | O6: High | Q6: ='⚙️ Config'!C5 -> Q3 2026 | R6: Product delivers 10/10 experience | S6: Commit | T6: None | U6: Completed ✅
B7: 3 | D7: Implement 3D Talent Galaxy on landing page | E7: Tech Lead | F7: Committed | G7: 0 | H7: 1 | I7: 1 | J7: =IFERROR(IF(H7=G7,IF(I7>=H7,1,0),(I7-G7)/(H7-G7)),0) -> 1 | K7: =IFERROR(AVERAGEIF(C5:C200,C7,J5:J200),"") | L7: 100 | M7: =IFERROR(IF(H7=G7,IF(I7>=H7,100,0),(I7-G7)/(H7-G7)*100),0) -> 100 | N7: =IF(M7="","",IF(M7>=90,"🏆 Supercharged",IF(M7>=70,"🟢 On Track",IF(M7>=40,"🟡 At Risk","🔴 Off Track")))) -> 🏆 Supercharged | O7: High | Q7: ='⚙️ Config'!C5 -> Q3 2026 | R7: Product delivers 10/10 experience | S7: Commit | T7: None | U7: Completed ✅
B8: 4 | D8: Achieve 95%+ uptime on Cloudflare Worker AI endpoint | E8: Tech Lead | F8: Committed | G8: 0 | H8: 95 | I8: 0 | J8: =IFERROR(IF(H8=G8,IF(I8>=H8,1,0),(I8-G8)/(H8-G8)),0) -> 0 | K8: =IFERROR(AVERAGEIF(C5:C200,C8,J5:J200),"") | L8: 100 | M8: =IFERROR(IF(H8=G8,IF(I8>=H8,100,0),(I8-G8)/(H8-G8)*100),0) -> 0 | N8: =IF(M8="","",IF(M8>=90,"🏆 Supercharged",IF(M8>=70,"🟢 On Track",IF(M8>=40,"🟡 At Risk","🔴 Off Track")))) -> 🔴 Off Track | O8: High | Q8: ='⚙️ Config'!C5 -> Q3 2026 | R8: Product delivers 10/10 experience | S8: Commit | T8: Cloudflare monitoring | U8: Track via CF dashboard
B9: 5 | C9: Marketing: Create content that makes HR professionals stop scrolling | D9: Write 15 LinkedIn posts for Day-1 campaign | E9: Growth Lead | F9: Committed | G9: 0 | H9: 15 | I9: 15 | J9: =IFERROR(IF(H9=G9,IF(I9>=H9,1,0),(I9-G9)/(H9-G9)),0) -> 1 | K9: =IFERROR(AVERAGEIF(C5:C200,C9,J5:J200),"") -> 1 | L9: 100 | M9: =IFERROR(IF(H9=G9,IF(I9>=H9,100,0),(I9-G9)/(H9-G9)*100),0) -> 100 | N9: =IF(M9="","",IF(M9>=90,"🏆 Supercharged",IF(M9>=70,"🟢 On Track",IF(M9>=40,"🟡 At Risk","🔴 Off Track")))) -> 🏆 Supercharged | O9: High | Q9: ='⚙️ Config'!C5 -> Q3 2026 | R9: Launch 15-post LinkedIn campaign | S9: Commit | T9: None | U9: Completed ✅
B10: 6 | D10: Create 5 carousel posts showing Spatial 9-Box wow-factor | E10: Growth Lead | F10: Aspirational | G10: 0 | H10: 5 | I10: 0 | J10: =IFERROR(IF(H10=G10,IF(I10>=H10,1,0),(I10-G10)/(H10-G10)),0) -> 0 | K10: =IFERROR(AVERAGEIF(C5:C200,C10,J5:J200),"") | L10: 100 | M10: =IFERROR(IF(H10=G10,IF(I10>=H10,100,0),(I10-G10)/(H10-G10)*100),0) -> 0 | N10: =IF(M10="","",IF(M10>=90,"🏆 Supercharged",IF(M10>=70,"🟢 On Track",IF(M10>=40,"🟡 At Risk","🔴 Off Track")))) -> 🔴 Off Track | O10: Medium | Q10: ='⚙️ Config'!C5 -> Q3 2026 | R10: Launch 15-post LinkedIn campaign | S10: Stretch | T10: Design assets ready | U10: Screenshots from platform
B11: 7 | D11: Identify and reach out to 10 HR newsletter editors | E11: Growth Lead | F11: Aspirational | G11: 0 | H11: 10 | I11: 0 | J11: =IFERROR(IF(H11=G11,IF(I11>=H11,1,0),(I11-G11)/(H11-G11)),0) -> 0 | K11: =IFERROR(AVERAGEIF(C5:C200,C11,J5:J200),"") | L11: 100 | M11: =IFERROR(IF(H11=G11,IF(I11>=H11,100,0),(I11-G11)/(H11-G11)*100),0) -> 0 | N11: =IF(M11="","",IF(M11>=90,"🏆 Supercharged",IF(M11>=70,"🟢 On Track",IF(M11>=40,"🟡 At Risk","🔴 Off Track")))) -> 🔴 Off Track | O11: Low | Q11: ='⚙️ Config'!C5 -> Q3 2026 | R11: Get featured in 3 HR newsletters | S11: Stretch | T11: None | U11: Research phase
B12: 8 | D12: Build a demo video of full platform walkthrough | E12: Growth Lead | F12: Aspirational | G12: 0 | H12: 1 | I12: 0 | J12: =IFERROR(IF(H12=G12,IF(I12>=H12,1,0),(I12-G12)/(H12-G12)),0) -> 0 | K12: =IFERROR(AVERAGEIF(C5:C200,C12,J5:J200),"") | L12: 100 | M12: =IFERROR(IF(H12=G12,IF(I12>=H12,100,0),(I12-G12)/(H12-G12)*100),0) -> 0 | N12: =IF(M12="","",IF(M12>=90,"🏆 Supercharged",IF(M12>=70,"🟢 On Track",IF(M12>=40,"🟡 At Risk","🔴 Off Track")))) -> 🔴 Off Track | O12: Low | Q12: ='⚙️ Config'!C5 -> Q3 2026 | R12: 500 signups in 30 days | S12: Stretch | T12: Screen recording tool | U12: < 3 min walk-through
B13: 9 | C13: Customer Success: Ensure every Pro user gets value in first 7 days | D13: Create onboarding email sequence (5 emails) | E13: CS Lead | F13: Committed | G13: 0 | H13: 5 | I13: 0 | J13: =IFERROR(IF(H13=G13,IF(I13>=H13,1,0),(I13-G13)/(H13-G13)),0) -> 0 | K13: =IFERROR(AVERAGEIF(C5:C200,C13,J5:J200),"") -> 0 | L13: 100 | M13: =IFERROR(IF(H13=G13,IF(I13>=H13,100,0),(I13-G13)/(H13-G13)*100),0) -> 0 | N13: =IF(M13="","",IF(M13>=90,"🏆 Supercharged",IF(M13>=70,"🟢 On Track",IF(M13>=40,"🟡 At Risk","🔴 Off Track")))) -> 🔴 Off Track | O13: Medium | Q13: ='⚙️ Config'!C5 -> Q3 2026 | R13: 500 email signups | S13: Commit | T13: Resend integration | U13: After payments live
B14: 10 | D14: Publish 10 help articles covering top user questions | E14: CS Lead | F14: Committed | G14: 0 | H14: 10 | I14: 0 | J14: =IFERROR(IF(H14=G14,IF(I14>=H14,1,0),(I14-G14)/(H14-G14)),0) -> 0 | K14: =IFERROR(AVERAGEIF(C5:C200,C14,J5:J200),"") | L14: 100 | M14: =IFERROR(IF(H14=G14,IF(I14>=H14,100,0),(I14-G14)/(H14-G14)*100),0) -> 0 | N14: =IF(M14="","",IF(M14>=90,"🏆 Supercharged",IF(M14>=70,"🟢 On Track",IF(M14>=40,"🟡 At Risk","🔴 Off Track")))) -> 🔴 Off Track | O14: Medium | Q14: ='⚙️ Config'!C5 -> Q3 2026 | R14: Ship 20 expert guides | S14: Commit | T14: None | U14: Identify questions from beta testing
B15: 11 | D15: Achieve < 24h first response time on support queries | E15: CS Lead | F15: Committed | G15: 0 | H15: 24 | I15: 0 | J15: =IFERROR(IF(H15=G15,IF(I15>=H15,1,0),(I15-G15)/(H15-G15)),0) -> 0 | K15: =IFERROR(AVERAGEIF(C5:C200,C15,J5:J200),"") | L15: 100 | M15: =IFERROR(IF(H15=G15,IF(I15>=H15,100,0),(I15-G15)/(H15-G15)*100),0) -> 0 | N15: =IF(M15="","",IF(M15>=90,"🏆 Supercharged",IF(M15>=70,"🟢 On Track",IF(M15>=40,"🟡 At Risk","🔴 Off Track")))) -> 🔴 Off Track | O15: High | Q15: ='⚙️ Config'!C5 -> Q3 2026 | R15: Achieve 4.5+ star rating | S15: Commit | T15: None | U15: Set up support inbox
B17: PERIOD SUMMARY | F17: Avg Google Score | G17: =IFERROR(AVERAGE(J5:J15),"—") -> 0.27272727 | H17: Avg SMART % | I17: =IFERROR(AVERAGE(M5:M15),"—") -> 27.272727 | J17: On Track KRs | K17: =COUNTIF(J5:J15,">=0.7") -> 3 | L17: At Risk KRs | M17: =COUNTIFS(J5:J15,">=0.4",J5:J15,"<0.7") -> 0 | N17: Off Track KRs | O17: =COUNTIF(J5:J15,"<0.4") -> 8

Sheet 👤 L4 Individual
B1: 👤 INDIVIDUAL OKRs · Level 4
B2: Blue cells = your inputs · Green cells = auto-calculated · Update "Current" columns weekly · Linked to ⚙️ Config
F3: GOOGLE OKR SCORING (0.0 – 1.0) | L3: SMART SCORING (%) | O3: STATUS & METADATA
B4: # | C4: OBJ # | D4: Objective | E4: Key Result | F4: Owner / DRI | G4: KR Type | H4: Baseline | I4: Stretch Target | J4: Current | K4: KR Score (0–1) | L4: Obj Score (0–1) | M4: Target (100%) | N4: Actual (%) | O4: SMART Score | P4: Confidence Level | Q4: Check-in Date | R4: Period | S4: Linked to Team OKR | T4: Stretch vs Commit | U4: Dependencies | V4: Notes
B5: 1 | C5: Vivek (Founder): Lead with clarity, speed, and product taste | D5: Ship 1 major product feature per week during Q3 | E5: Vivek | F5: Committed | G5: 0 | H5: 13 | I5: 6 | J5: =IFERROR(IF(H5=G5,IF(I5>=H5,1,0),(I5-G5)/(H5-G5)),0) -> 0.46153846 | K5: =IFERROR(AVERAGEIF(C5:C200,C5,J5:J200),"") -> 0.46153846 | L5: 100 | M5: =IFERROR(IF(H5=G5,IF(I5>=H5,100,0),(I5-G5)/(H5-G5)*100),0) -> 46.153846 | N5: =IF(M5="","",IF(M5>=90,"🏆 Supercharged",IF(M5>=70,"🟢 On Track",IF(M5>=40,"🟡 At Risk","🔴 Off Track")))) -> 🟡 At Risk | O5: High | Q5: ='⚙️ Config'!C5 -> Q3 2026 | R5: Engineering team OKR | S5: Commit | T5: Claude AI build sessions | U5: 6 weeks of sessions done
B6: 2 | D6: Record all platform decisions in a decision log | E6: Vivek | F6: Committed | G6: 0 | H6: 1 | I6: 0 | J6: =IFERROR(IF(H6=G6,IF(I6>=H6,1,0),(I6-G6)/(H6-G6)),0) -> 0 | K6: =IFERROR(AVERAGEIF(C5:C200,C6,J5:J200),"") | L6: 100 | M6: =IFERROR(IF(H6=G6,IF(I6>=H6,100,0),(I6-G6)/(H6-G6)*100),0) -> 0 | N6: =IF(M6="","",IF(M6>=90,"🏆 Supercharged",IF(M6>=70,"🟢 On Track",IF(M6>=40,"🟡 At Risk","🔴 Off Track")))) -> 🔴 Off Track | O6: Low | Q6: ='⚙️ Config'!C5 -> Q3 2026 | R6: People & Culture OKR | S6: Commit | T6: None | U6: Notion doc needed
B7: 3 | D7: Close first 100 paying Pro subscribers personally | E7: Vivek | F7: Aspirational | G7: 0 | H7: 100 | I7: 0 | J7: =IFERROR(IF(H7=G7,IF(I7>=H7,1,0),(I7-G7)/(H7-G7)),0) -> 0 | K7: =IFERROR(AVERAGEIF(C5:C200,C7,J5:J200),"") | L7: 100 | M7: =IFERROR(IF(H7=G7,IF(I7>=H7,100,0),(I7-G7)/(H7-G7)*100),0) -> 0 | N7: =IF(M7="","",IF(M7>=90,"🏆 Supercharged",IF(M7>=70,"🟢 On Track",IF(M7>=40,"🟡 At Risk","🔴 Off Track")))) -> 🔴 Off Track | O7: Low | Q7: ='⚙️ Config'!C5 -> Q3 2026 | R7: Reach 10k subscribers | S7: Stretch | T7: Gumroad live | U7: Outreach + LinkedIn
B8: 4 | D8: Complete INC 20A filing and bank account activation | E8: Vivek | F8: Committed | G8: 0 | H8: 1 | I8: 0 | J8: =IFERROR(IF(H8=G8,IF(I8>=H8,1,0),(I8-G8)/(H8-G8)),0) -> 0 | K8: =IFERROR(AVERAGEIF(C5:C200,C8,J5:J200),"") | L8: 100 | M8: =IFERROR(IF(H8=G8,IF(I8>=H8,100,0),(I8-G8)/(H8-G8)*100),0) -> 0 | N8: =IF(M8="","",IF(M8>=90,"🏆 Supercharged",IF(M8>=70,"🟢 On Track",IF(M8>=40,"🟡 At Risk","🔴 Off Track")))) -> 🔴 Off Track | O8: Medium | Q8: ='⚙️ Config'!C5 -> Q3 2026 | R8: Financial sustainability | S8: Commit | T8: CA / bank | U8: Blocking Razorpay
B9: 5 | C9: CPO: Define and ship a product roadmap that users love | D9: Write detailed PRD for each new feature before build | E9: CPO | F9: Committed | G9: 0 | H9: 4 | I9: 4 | J9: =IFERROR(IF(H9=G9,IF(I9>=H9,1,0),(I9-G9)/(H9-G9)),0) -> 1 | K9: =IFERROR(AVERAGEIF(C5:C200,C9,J5:J200),"") -> 1 | L9: 100 | M9: =IFERROR(IF(H9=G9,IF(I9>=H9,100,0),(I9-G9)/(H9-G9)*100),0) -> 100 | N9: =IF(M9="","",IF(M9>=90,"🏆 Supercharged",IF(M9>=70,"🟢 On Track",IF(M9>=40,"🟡 At Risk","🔴 Off Track")))) -> 🏆 Supercharged | O9: High | Q9: ='⚙️ Config'!C5 -> Q3 2026 | R9: Ship features on time | S9: Commit | T9: None | U9: 4 PRDs done this quarter
B10: 6 | D10: Conduct 10 user interviews with HR professionals | E10: CPO | F10: Aspirational | G10: 0 | H10: 10 | I10: 2 | J10: =IFERROR(IF(H10=G10,IF(I10>=H10,1,0),(I10-G10)/(H10-G10)),0) -> 0.2 | K10: =IFERROR(AVERAGEIF(C5:C200,C10,J5:J200),"") | L10: 100 | M10: =IFERROR(IF(H10=G10,IF(I10>=H10,100,0),(I10-G10)/(H10-G10)*100),0) -> 20 | N10: =IF(M10="","",IF(M10>=90,"🏆 Supercharged",IF(M10>=70,"🟢 On Track",IF(M10>=40,"🟡 At Risk","🔴 Off Track")))) -> 🔴 Off Track | O10: Medium | Q10: ='⚙️ Config'!C5 -> Q3 2026 | R10: Achieve 4.5 star rating | S10: Stretch | T10: Beta tester list | U10: 2 done, 8 remaining
B11: 7 | D11: Define pricing v2 (₹1499 India / $25 Global) | E11: CPO | F11: Committed | G11: 0 | H11: 1 | I11: 0 | J11: =IFERROR(IF(H11=G11,IF(I11>=H11,1,0),(I11-G11)/(H11-G11)),0) -> 0 | K11: =IFERROR(AVERAGEIF(C5:C200,C11,J5:J200),"") | L11: 100 | M11: =IFERROR(IF(H11=G11,IF(I11>=H11,100,0),(I11-G11)/(H11-G11)*100),0) -> 0 | N11: =IF(M11="","",IF(M11>=90,"🏆 Supercharged",IF(M11>=70,"🟢 On Track",IF(M11>=40,"🟡 At Risk","🔴 Off Track")))) -> 🔴 Off Track | O11: High | Q11: ='⚙️ Config'!C5 -> Q3 2026 | R11: Financial sustainability | S11: Commit | T11: None | U11: Decision made, page needs update
B12: 8 | D12: Ship OKR flagship Excel to Downloads Library | E12: CPO | F12: Committed | G12: 0 | H12: 1 | I12: 0 | J12: =IFERROR(IF(H12=G12,IF(I12>=H12,1,0),(I12-G12)/(H12-G12)),0) -> 0 | K12: =IFERROR(AVERAGEIF(C5:C200,C12,J5:J200),"") | L12: 100 | M12: =IFERROR(IF(H12=G12,IF(I12>=H12,100,0),(I12-G12)/(H12-G12)*100),0) -> 0 | N12: =IF(M12="","",IF(M12>=90,"🏆 Supercharged",IF(M12>=70,"🟢 On Track",IF(M12>=40,"🟡 At Risk","🔴 Off Track")))) -> 🔴 Off Track | O12: High | Q12: ='⚙️ Config'!C5 -> Q3 2026 | R12: Build product replacing enterprise | S12: Commit | T12: None | U12: In progress right now 🔨
B14: PERIOD SUMMARY | F14: Avg Google Score | G14: =IFERROR(AVERAGE(J5:J12),"—") -> 0.20769231 | H14: Avg SMART % | I14: =IFERROR(AVERAGE(M5:M12),"—") -> 20.769231 | J14: On Track KRs | K14: =COUNTIF(J5:J12,">=0.7") -> 1 | L14: At Risk KRs | M14: =COUNTIFS(J5:J12,">=0.4",J5:J12,"<0.7") -> 1 | N14: Off Track KRs | O14: =COUNTIF(J5:J12,"<0.4") -> 6

Sheet 🌡️ Health Dashboard
B1: 🌡️ OKR HEALTH DASHBOARD — CHRO VIEW
B2: Live summary — all formulas pull from L1–L4 sheets automatically. Update current values there to refresh.
B4: COMPANY | E4: DEPT | H4: TEAM | K4: INDIV.
B5: =IFERROR(AVERAGE('🏢 L1 Company OKRs'!J5:J50),"—") -> 0.27581818 | E5: =IFERROR(AVERAGE('🏬 L2 Dept OKRs'!J5:J60),"—") -> 0.11818182 | H5: =IFERROR(AVERAGE('👥 L3 Team OKRs'!J5:J60),"—") -> 0.27272727 | K5: =IFERROR(AVERAGE('👤 L4 Individual'!J5:J60),"—") -> 0.20769231
B6: =IF(ISNUMBER(B5),IF(B5>=0.7,"🟢 ON TRACK",IF(B5>=0.4,"🟡 AT RISK","🔴 OFF TRACK")),"—") -> 🔴 OFF TRACK | E6: =IF(ISNUMBER(E5),IF(E5>=0.7,"🟢 ON TRACK",IF(E5>=0.4,"🟡 AT RISK","🔴 OFF TRACK")),"—") -> 🔴 OFF TRACK | H6: =IF(ISNUMBER(H5),IF(H5>=0.7,"🟢 ON TRACK",IF(H5>=0.4,"🟡 AT RISK","🔴 OFF TRACK")),"—") -> 🔴 OFF TRACK | K6: =IF(ISNUMBER(K5),IF(K5>=0.7,"🟢 ON TRACK",IF(K5>=0.4,"🟡 AT RISK","🔴 OFF TRACK")),"—") -> 🔴 OFF TRACK
B8: KR BREAKDOWN BY STATUS
B9: Level | C9: Total KRs | D9: 🏆 Supercharged (≥0.9) | E9: 🟢 On Track (0.7–0.89) | F9: 🟡 At Risk (0.4–0.69) | G9: 🔴 Off Track (<0.4) | H9: Avg Score | I9: Coverage %
B10: Company L1 | C10: =COUNTA('🏢 L1 Company OKRs'!J5:J50) -> 12 | D10: =COUNTIF('🏢 L1 Company OKRs'!J5:J50,">=0.9") -> 3 | E10: =COUNTIFS('🏢 L1 Company OKRs'!J5:J50,">=0.7",'🏢 L1 Company OKRs'!J5:J50,"<0.9") -> 0 | F10: =COUNTIFS('🏢 L1 Company OKRs'!J5:J50,">=0.4",'🏢 L1 Company OKRs'!J5:J50,"<0.7") -> 0 | G10: =COUNTIF('🏢 L1 Company OKRs'!J5:J50,"<0.4") -> 8 | H10: =IFERROR(AVERAGE('🏢 L1 Company OKRs'!J5:J50),"—") -> 0.27581818 | I10: —
B11: Dept L2 | C11: =COUNTA('🏬 L2 Dept OKRs'!J5:J60) -> 12 | D11: =COUNTIF('🏬 L2 Dept OKRs'!J5:J60,">=0.9") -> 0 | E11: =COUNTIFS('🏬 L2 Dept OKRs'!J5:J60,">=0.7",'🏬 L2 Dept OKRs'!J5:J60,"<0.9") -> 1 | F11: =COUNTIFS('🏬 L2 Dept OKRs'!J5:J60,">=0.4",'🏬 L2 Dept OKRs'!J5:J60,"<0.7") -> 1 | G11: =COUNTIF('🏬 L2 Dept OKRs'!J5:J60,"<0.4") -> 9 | H11: =IFERROR(AVERAGE('🏬 L2 Dept OKRs'!J5:J60),"—") -> 0.11818182 | I11: —
B12: Team L3 | C12: =COUNTA('👥 L3 Team OKRs'!J5:J60) -> 12 | D12: =COUNTIF('👥 L3 Team OKRs'!J5:J60,">=0.9") -> 3 | E12: =COUNTIFS('👥 L3 Team OKRs'!J5:J60,">=0.7",'👥 L3 Team OKRs'!J5:J60,"<0.9") -> 0 | F12: =COUNTIFS('👥 L3 Team OKRs'!J5:J60,">=0.4",'👥 L3 Team OKRs'!J5:J60,"<0.7") -> 0 | G12: =COUNTIF('👥 L3 Team OKRs'!J5:J60,"<0.4") -> 8 | H12: =IFERROR(AVERAGE('👥 L3 Team OKRs'!J5:J60),"—") -> 0.27272727 | I12: —
B13: Individual L4 | C13: =COUNTA('👤 L4 Individual'!J5:J60) -> 9 | D13: =COUNTIF('👤 L4 Individual'!J5:J60,">=0.9") -> 1 | E13: =COUNTIFS('👤 L4 Individual'!J5:J60,">=0.7",'👤 L4 Individual'!J5:J60,"<0.9") -> 0 | F13: =COUNTIFS('👤 L4 Individual'!J5:J60,">=0.4",'👤 L4 Individual'!J5:J60,"<0.7") -> 1 | G13: =COUNTIF('👤 L4 Individual'!J5:J60,"<0.4") -> 6 | H13: =IFERROR(AVERAGE('👤 L4 Individual'!J5:J60),"—") -> 0.20769231 | I13: —

Sheet 📅 Check-in Log
B1: 📅 WEEKLY OKR CHECK-IN LOG
B2: Update confidence + current values every week. Trend arrow auto-calculates from last 2 check-ins.
B3: Week | C3: Date | D3: Objective | E3: Key Result | F3: Level | G3: Owner | H3: Last Score | I3: This Score | J3: Trend | K3: Confidence | L3: Blocker? | M3: Action Agreed | N3: Next Check-in
B4: 1 | H4: 0 | J4: =IF(H4="","",IF(H4>G4,"⬆ Improving",IF(H4<G4,"⬇ Declining","➡ Stable"))) -> ➡ Stable | K4: High
B5: 2 | H5: 0 | J5: =IF(H5="","",IF(H5>G5,"⬆ Improving",IF(H5<G5,"⬇ Declining","➡ Stable"))) -> ➡ Stable | K5: High
B6: 3 | H6: 0 | J6: =IF(H6="","",IF(H6>G6,"⬆ Improving",IF(H6<G6,"⬇ Declining","➡ Stable"))) -> ➡ Stable | K6: High
B7: 4 | H7: 0 | J7: =IF(H7="","",IF(H7>G7,"⬆ Improving",IF(H7<G7,"⬇ Declining","➡ Stable"))) -> ➡ Stable | K7: High
B8: 5 | H8: 0 | J8: =IF(H8="","",IF(H8>G8,"⬆ Improving",IF(H8<G8,"⬇ Declining","➡ Stable"))) -> ➡ Stable | K8: High
B9: 6 | H9: 0 | J9: =IF(H9="","",IF(H9>G9,"⬆ Improving",IF(H9<G9,"⬇ Declining","➡ Stable"))) -> ➡ Stable | K9: High
B10: 7 | H10: 0 | J10: =IF(H10="","",IF(H10>G10,"⬆ Improving",IF(H10<G10,"⬇ Declining","➡ Stable"))) -> ➡ Stable | K10: High
B11: 8 | H11: 0 | J11: =IF(H11="","",IF(H11>G11,"⬆ Improving",IF(H11<G11,"⬇ Declining","➡ Stable"))) -> ➡ Stable | K11: High
B12: 9 | H12: 0 | J12: =IF(H12="","",IF(H12>G12,"⬆ Improving",IF(H12<G12,"⬇ Declining","➡ Stable"))) -> ➡ Stable | K12: High
B13: 10 | H13: 0 | J13: =IF(H13="","",IF(H13>G13,"⬆ Improving",IF(H13<G13,"⬇ Declining","➡ Stable"))) -> ➡ Stable | K13: High
B14: 11 | H14: 0 | J14: =IF(H14="","",IF(H14>G14,"⬆ Improving",IF(H14<G14,"⬇ Declining","➡ Stable"))) -> ➡ Stable | K14: High
B15: 12 | H15: 0 | J15: =IF(H15="","",IF(H15>G15,"⬆ Improving",IF(H15<G15,"⬇ Declining","➡ Stable"))) -> ➡ Stable | K15: High
... B31: 28 | H31: 0 | J31: =IF(H31="","",IF(H31>G31,"⬆ Improving",IF(H31<G31,"⬇ Declining","➡ Stable"))) -> ➡ Stable | K31: High

Sheet ⚡ Stretch vs Commit
B1: ⚡ STRETCH vs COMMITTED OKR TRACKER
B2: Aspirational OKRs: target 0.7 (reaching 1.0 means you didn't stretch enough). Committed: must hit 1.0.
B4: 📖 THE GOOGLE RULE: Aspirational OKRs averaging 0.7 = perfect. If you're hitting 1.0 every time, your targets aren't ambitious enough.
B5: Committed OKRs: must hit 1.0. Missing these has direct consequences. Use sparingly — max 1 committed per objective.
B7: Objective | C7: Key Result | D7: Type | E7: Owner | F7: Target | G7: Current | H7: Score | I7: Status | J7: Ideal Range | K7: Gap to Ideal
B8: Reach 10k Pro subscribers | C8: Reach 10,000 active Pro subscribers globally | D8: Aspirational | E8: CEO | F8: 10000 | G8: 340 | H8: =IFERROR(F8/E8,0) -> 0 | I8: =IF(C8="Aspirational",IF(H8>=0.9,"⚠️ Too Easy?",IF(H8>=0.7,"🟢 Perfect Stretch",IF(H8>=0.4,"🟡 Pushing",IF(H8>0,"🔴 Far Off","—")))),IF(H8>=1,"✅ Committed Hit",IF(H8>=0.7,"🟡 Committed Risk","🔴 COMMITTED MISS"))) -> 🔴 COMMITTED MISS | J8: 0.6 – 0.8 ideal | K8: =IF(C8="Aspirational",IF(H8<0.7,0.7-H8,0),IF(H8<1,1-H8,0)) -> 1
B9: Build product replacing enterprise tools | C9: Ship Goal Diagnostic Lab | D9: Committed | E9: CPO | F9: 1 | G9: 1 | H9: =IFERROR(F9/E9,0) -> 0 | I9: =IF(C9="Aspirational",IF(H9>=0.9,"⚠️ Too Easy?",IF(H9>=0.7,"🟢 Perfect Stretch",IF(H9>=0.4,"🟡 Pushing",IF(H9>0,"🔴 Far Off","—")))),IF(H9>=1,"✅ Committed Hit",IF(H9>=0.7,"🟡 Committed Risk","🔴 COMMITTED MISS"))) -> 🔴 COMMITTED MISS | J9: 1.0 required | K9: =IF(C9="Aspirational",IF(H9<0.7,0.7-H9,0),IF(H9<1,1-H9,0)) -> 1
B10: Build product replacing enterprise tools | C10: Ship Bias Audit module | D10: Committed | E10: CPO | F10: 1 | G10: 1 | H10: =IFERROR(F10/E10,0) -> 0 | I10: =IF(C10="Aspirational",IF(H10>=0.9,"⚠️ Too Easy?",IF(H10>=0.7,"🟢 Perfect Stretch",IF(H10>=0.4,"🟡 Pushing",IF(H10>0,"🔴 Far Off","—")))),IF(H10>=1,"✅ Committed Hit",IF(H10>=0.7,"🟡 Committed Risk","🔴 COMMITTED MISS"))) -> 🔴 COMMITTED MISS | J10: 1.0 required | K10: =IF(C10="Aspirational",IF(H10<0.7,0.7-H10,0),IF(H10<1,1-H10,0)) -> 1
B11: Financial sustainability | C11: Hit ₹50L ARR | D11: Aspirational | E11: CFO | F11: 5000000 | G11: 0 | H11: =IFERROR(F11/E11,0) -> 0 | I11: =IF(C11="Aspirational",IF(H11>=0.9,"⚠️ Too Easy?",IF(H11>=0.7,"🟢 Perfect Stretch",IF(H11>=0.4,"🟡 Pushing",IF(H11>0,"🔴 Far Off","—")))),IF(H11>=1,"✅ Committed Hit",IF(H11>=0.7,"🟡 Committed Risk","🔴 COMMITTED MISS"))) -> 🔴 COMMITTED MISS | J11: 0.6 – 0.8 ideal | K11: =IF(C11="Aspirational",IF(H11<0.7,0.7-H11,0),IF(H11<1,1-H11,0)) -> 1

Sheet 📖 Scoring Guide
B1: 📖 OKR SCORING METHODOLOGY GUIDE
B2: GOOGLE OKR MODEL (0.0 – 1.0)
B3: Score | C3: Label | D3: Meaning | E3: For Aspirational OKRs | F3: For Committed OKRs
B4: 0.9 – 1.0 | C4: 🏆 Supercharged | D4: Exceptional result | E4: Means your target wasn't ambitious enough | F4: Required — anything less is a miss
B5: 0.7 – 0.89 | C5: 🟢 On Track | D5: Good progress | E5: This is the GOLD STANDARD target | F5: Approaching required zone
B6: 0.4 – 0.69 | C6: 🟡 At Risk | D6: Progress but lagging | E6: Acceptable for tough aspirational KRs | F6: High concern — needs intervention
B7: 0.0 – 0.39 | C7: 🔴 Off Track | D7: Significant gap | E7: Needs review — too ambitious or under-resourced | F7: Critical — immediate escalation
B9: THE GOOGLE RULE
B10: Key Principle | G10: If you always hit 1.0 on aspirational OKRs, they were never ambitious enough. 0.7 is the deliberate target — the discomfort zone where real growth happens. Andy Grove invented this at Intel. Larry Page enforced it at Google.
B12: SMART KR MODEL (%)
B13: Score | C13: Label | D13: Meaning | E13: Action
B14: 90 – 100% | C14: 🏆 Supercharged | D14: KR exceeded | E14: Celebrate + set harder next cycle
B15: 70 – 89% | C15: 🟢 On Track | D15: Good delivery | E15: Continue, minor adjustments
B16: 40 – 69% | C16: 🟡 At Risk | D16: Partial delivery | E16: Review resources, blockers, timeline
B17: 0 – 39% | C17: 🔴 Off Track | D17: Significant miss | E17: Escalate, reset, or cancel the KR
B19: KR TYPE DEFINITIONS
B20: Aspirational | C20: Also called Moonshot or Stretch | D20: Target: 0.7 (Google model) | E20: Set 3–4x harder than you think is possible | F20: Never punish missing aspirational KRs
B21: Committed | C21: Must-do, non-negotiable | D21: Target: 1.0 | E21: These are promises, not aspirations | F21: Missing a committed KR has consequences
B23: CONFIDENCE LEVELS
B24: High | C24: On track to hit target | D24: No intervention needed | E24: Weekly check-in sufficient
B25: Medium | C25: Some risk to delivery | D25: Monitor weekly | E25: Blocker identified but manageable
B26: Low | C26: Significant risk | D26: Immediate manager attention | E26: Escalate, add resource, or descope

Sheet 🔗 Dependencies
B1: 🔗 CROSS-FUNCTIONAL OKR DEPENDENCY MAP
B2: Track which KRs depend on another team delivering. Flag blockers early. Escalate to CHRO if dependency is missed.
B3: Our KR | C3: Depends On (KR) | D3: Our Team | E3: Delivering Team | F3: Owner | G3: Due Date | H3: Status | I3: Risk if Missed | J3: Escalation Path
B4: 500 email signups in 30 days | C4: Resend email integration | D4: Growth | E4: Engineering | F4: Tech Lead | G4: 01 Aug 2026 | H4: Blocked | I4: Cannot collect emails without tool | J4: Escalate to CPO
B5: Reach 10k Pro subscribers | C5: Gumroad international payments | D5: Growth | E5: Founder / Finance | F5: Vivek | G5: 15 Jun 2026 | H5: In Progress | I5: Zero paid signups possible | J5: Founder personal action
B6: Hit ₹50L ARR | C6: Razorpay KYC + INC 20A filing | D6: Finance | E6: Legal / CA | F6: Vivek / CA | G6: 30 Jun 2026 | H6: Blocked — INC 20A pending | I6: Zero India revenue | J6: Escalate to CA
B7: Ship Conversation Simulator v2 | C7: D-ID API access + budget | D7: Product | E7: Founder | F7: Vivek | G7: Q4 2026 | H7: Deferred | I7: Lip-sync feature blocked | J7: Post-revenue decision
B8: NPS score 65+ | C8: In-app survey widget | D8: CPO | E8: Engineering | F8: Tech Lead | G8: 01 Aug 2026 | H8: Not Started | I8: Cannot measure NPS | J8: Add to sprint backlog

Sheet 📊 Cascade View
B1: 📊 FULL OKR CASCADE VIEW — Company → Dept → Team → Individual
B2: Read-only summary. This sheet shows the full 4-level cascade so CHROs can see alignment in one view. Edit data in the individual level sheets.
C3: Level | D3: Objective | E3: Key Result | F3: Owner | G3: KR Score | H3: SMART % | I3: Badge | J3: Type | K3: Period | L3: Notes
B4: ▶ L1 — 🏢 L1 Company OKRs
B5: L1 | C5: =IF('🏢 L1 Company OKRs'!C5="","",'🏢 L1 Company OKRs'!C5) -> Establish Virorah PMS as the #1 HR EdTech platform in India by end of 2026 | D5: =IF('🏢 L1 Company OKRs'!D5="","",'🏢 L1 Company OKRs'!D5) -> Reach 10,000 active Pro subscribers globally | E5: =IF('🏢 L1 Company OKRs'!E5="","",'🏢 L1 Company OKRs'!E5) -> CEO | F5: =IFERROR('🏢 L1 Company OKRs'!J5,"") -> 0.034 | G5: =IFERROR('🏢 L1 Company OKRs'!M5,"") -> 3.4 | H5: =IFERROR('🏢 L1 Company OKRs'!N5,"") -> 🔴 Off Track | I5: =IFERROR('🏢 L1 Company OKRs'!F5,"") -> Aspirational | J5: =IFERROR('🏢 L1 Company OKRs'!Q5,"") -> Q3 2026 | K5: =IFERROR('🏢 L1 Company OKRs'!U5,"") -> Primary growth KR
B6: L1 | C6: =IF('🏢 L1 Company OKRs'!C6="","",'🏢 L1 Company OKRs'!C6) | D6: =IF('🏢 L1 Company OKRs'!D6="","",'🏢 L1 Company OKRs'!D6) -> Achieve Net Promoter Score of 65+ from Pro users | E6: =IF('🏢 L1 Company OKRs'!E6="","",'🏢 L1 Company OKRs'!E6) -> CPO | F6: =IFERROR('🏢 L1 Company OKRs'!J6,"") -> 0 | G6: =IFERROR('🏢 L1 Company OKRs'!M6,"") -> 0 | H6: =IFERROR('🏢 L1 Company OKRs'!N6,"") -> 🔴 Off Track | I6: =IFERROR('🏢 L1 Company OKRs'!F6,"") -> Committed | J6: =IFERROR('🏢 L1 Company OKRs'!Q6,"") -> Q3 2026 | K6: =IFERROR('🏢 L1 Company OKRs'!U6,"") -> First survey at 500 users
B7: L1 | C7: =IF('🏢 L1 Company OKRs'!C7="","",'🏢 L1 Company OKRs'!C7) | D7: =IF('🏢 L1 Company OKRs'!D7="","",'🏢 L1 Company OKRs'!D7) -> Launch in 3 international markets (SG, UAE, UK) | E7: =IF('🏢 L1 Company OKRs'!E7="","",'🏢 L1 Company OKRs'!E7) -> CMO | F7: =IFERROR('🏢 L1 Company OKRs'!J7,"") -> 0 | G7: =IFERROR('🏢 L1 Company OKRs'!M7,"") -> 0 | H7: =IFERROR('🏢 L1 Company OKRs'!N7,"") -> 🔴 Off Track | I7: =IFERROR('🏢 L1 Company OKRs'!F7,"") -> Aspirational | J7: =IFERROR('🏢 L1 Company OKRs'!Q7,"") -> Q3 2026 | K7: =IFERROR('🏢 L1 Company OKRs'!U7,"") -> Gumroad live = auto-unlock
B8: L1 | C8: =IF('🏢 L1 Company OKRs'!C8="","",'🏢 L1 Company OKRs'!C8) | D8: =IF('🏢 L1 Company OKRs'!D8="","",'🏢 L1 Company OKRs'!D8) -> Secure DPIIT Startup India recognition | E8: =IF('🏢 L1 Company OKRs'!E8="","",'🏢 L1 Company OKRs'!E8) -> CFO | F8: =IFERROR('🏢 L1 Company OKRs'!J8,"") -> 0 | G8: =IFERROR('🏢 L1 Company OKRs'!M8,"") -> 0 | H8: =IFERROR('🏢 L1 Company OKRs'!N8,"") -> 🔴 Off Track | I8: =IFERROR('🏢 L1 Company OKRs'!F8,"") -> Committed | J8: =IFERROR('🏢 L1 Company OKRs'!Q8,"") -> Q3 2026 | K8: =IFERROR('🏢 L1 Company OKRs'!U8,"") -> CA handling
B9: L1 | C9: =IF('🏢 L1 Company OKRs'!C9="","",'🏢 L1 Company OKRs'!C9) -> Build a product that genuinely replaces enterprise PMS tools at 5% of their cost | D9: =IF('🏢 L1 Company OKRs'!D9="","",'🏢 L1 Company OKRs'!D9) -> Ship Goal Diagnostic Lab + Bias Audit to 100% of Pro users | E9: =IF('🏢 L1 Company OKRs'!E9="","",'🏢 L1 Company OKRs'!E9) -> CPO | F9: =IFERROR('🏢 L1 Company OKRs'!J9,"") -> 1 | G9: =IFERROR('🏢 L1 Company OKRs'!M9,"") -> 100 | H9: =IFERROR('🏢 L1 Company OKRs'!N9,"") -> 🏆 Supercharged | I9: =IFERROR('🏢 L1 Company OKRs'!F9,"") -> Committed | J9: =IFERROR('🏢 L1 Company OKRs'!Q9,"") -> Q3 2026 | K9: =IFERROR('🏢 L1 Company OKRs'!U9,"") -> Completed ✅
B10: L1 | C10: =IF('🏢 L1 Company OKRs'!C10="","",'🏢 L1 Company OKRs'!C10) | D10: =IF('🏢 L1 Company OKRs'!D10="","",'🏢 L1 Company OKRs'!D10) -> Deliver 3 enterprise-grade Excel toolkits in Downloads Library | E10: =IF('🏢 L1 Company OKRs'!E10="","",'🏢 L1 Company OKRs'!E10) -> CPO | F10: =IFERROR('🏢 L1 Company OKRs'!J10,"") -> 1 | G10: =IFERROR('🏢 L1 Company OKRs'!M10,"") -> 100 | H10: =IFERROR('🏢 L1 Company OKRs'!N10,"") -> 🏆 Supercharged | I10: =IFERROR('🏢 L1 Company OKRs'!F10,"") -> Committed | J10: =IFERROR('🏢 L1 Company OKRs'!Q10,"") -> Q3 2026 | K10: =IFERROR('🏢 L1 Company OKRs'!U10,"") -> Completed ✅
B11: L1 | C11: =IF('🏢 L1 Company OKRs'!C11="","",'🏢 L1 Company OKRs'!C11) | D11: =IF('🏢 L1 Company OKRs'!D11="","",'🏢 L1 Company OKRs'!D11) -> Achieve < 3 min time-to-first-insight from sign-up | E11: =IF('🏢 L1 Company OKRs'!E11="","",'🏢 L1 Company OKRs'!E11) -> CTO | F11: =IFERROR('🏢 L1 Company OKRs'!J11,"") -> 0 | G11: =IFERROR('🏢 L1 Company OKRs'!M11,"") -> 0 | H11: =IFERROR('🏢 L1 Company OKRs'!N11,"") -> 🔴 Off Track | I11: =IFERROR('🏢 L1 Company OKRs'!F11,"") -> Aspirational | J11: =IFERROR('🏢 L1 Company OKRs'!Q11,"") -> Q3 2026 | K11: =IFERROR('🏢 L1 Company OKRs'!U11,"") -> Track via GA4
B12: L1 | C12: =IF('🏢 L1 Company OKRs'!C12="","",'🏢 L1 Company OKRs'!C12) | D12: =IF('🏢 L1 Company OKRs'!D12="","",'🏢 L1 Company OKRs'!D12) -> Launch 4 Pro certifications with unique credential IDs | E12: =IF('🏢 L1 Company OKRs'!E12="","",'🏢 L1 Company OKRs'!E12) -> CPO | F12: =IFERROR('🏢 L1 Company OKRs'!J12,"") -> 1 | G12: =IFERROR('🏢 L1 Company OKRs'!M12,"") -> 100 | H12: =IFERROR('🏢 L1 Company OKRs'!N12,"") -> 🏆 Supercharged | I12: =IFERROR('🏢 L1 Company OKRs'!F12,"") -> Committed | J12: =IFERROR('🏢 L1 Company OKRs'!Q12,"") -> Q3 2026 | K12: =IFERROR('🏢 L1 Company OKRs'!U12,"") -> All 4 live
B13: L1 | C13: =IF('🏢 L1 Company OKRs'!C13="","",'🏢 L1 Company OKRs'!C13) -> Achieve financial sustainability within 12 months of launch | D13: =IF('🏢 L1 Company OKRs'!D13="","",'🏢 L1 Company OKRs'!D13) -> Hit ₹50L ARR by end of FY2026 | E13: =IF('🏢 L1 Company OKRs'!E13="","",'🏢 L1 Company OKRs'!E13) -> CEO | F13: =IFERROR('🏢 L1 Company OKRs'!J13,"") -> 0 | G13: =IFERROR('🏢 L1 Company OKRs'!M13,"") -> 0 | H13: =IFERROR('🏢 L1 Company OKRs'!N13,"") -> 🔴 Off Track | I13: =IFERROR('🏢 L1 Company OKRs'!F13,"") -> Aspirational | J13: =IFERROR('🏢 L1 Company OKRs'!Q13,"") -> Q3 2026 | K13: =IFERROR('🏢 L1 Company OKRs'!U13,"") -> Gumroad + Razorpay needed
B14: L1 | C14: =IF('🏢 L1 Company OKRs'!C14="","",'🏢 L1 Company OKRs'!C14) | D14: =IF('🏢 L1 Company OKRs'!D14="","",'🏢 L1 Company OKRs'!D14) -> Keep monthly burn below ₹8L | E14: =IF('🏢 L1 Company OKRs'!E14="","",'🏢 L1 Company OKRs'!E14) -> CFO | F14: =IFERROR('🏢 L1 Company OKRs'!J14,"") -> 0 | G14: =IFERROR('🏢 L1 Company OKRs'!M14,"") -> 0 | H14: =IFERROR('🏢 L1 Company OKRs'!N14,"") -> 🔴 Off Track | I14: =IFERROR('🏢 L1 Company OKRs'!F14,"") -> Committed | J14: =IFERROR('🏢 L1 Company OKRs'!Q14,"") -> Q3 2026 | K14: =IFERROR('🏢 L1 Company OKRs'!U14,"") -> Track monthly
B15: L1 | C15: =IF('🏢 L1 Company OKRs'!C15="","",'🏢 L1 Company OKRs'!C15) | D15: =IF('🏢 L1 Company OKRs'!D15="","",'🏢 L1 Company OKRs'!D15) -> Achieve 40% gross margin on Pro subscriptions | E15: =IF('🏢 L1 Company OKRs'!E15="","",'🏢 L1 Company OKRs'!E15) -> CFO | F15: =IFERROR('🏢 L1 Company OKRs'!J15,"") -> 0 | G15: =IFERROR('🏢 L1 Company OKRs'!M15,"") -> 0 | H15: =IFERROR('🏢 L1 Company OKRs'!N15,"") -> 🔴 Off Track | I15: =IFERROR('🏢 L1 Company OKRs'!F15,"") -> Aspirational | J15: =IFERROR('🏢 L1 Company OKRs'!Q15,"") -> Q3 2026 | K15: =IFERROR('🏢 L1 Company OKRs'!U15,"") -> After 500 paying users
B16: L1 | C16: =IF('🏢 L1 Company OKRs'!C16="","",'🏢 L1 Company OKRs'!C16) | D16: =IF('🏢 L1 Company OKRs'!D16="","",'🏢 L1 Company OKRs'!D16) | E16: =IF('🏢 L1 Company OKRs'!E16="","",'🏢 L1 Company OKRs'!E16) | F16: =IFERROR('🏢 L1 Company OKRs'!J16,"") -> 0 | G16: =IFERROR('🏢 L1 Company OKRs'!M16,"") -> 0 | H16: =IFERROR('🏢 L1 Company OKRs'!N16,"") -> 0 | I16: =IFERROR('🏢 L1 Company OKRs'!F16,"") -> 0 | J16: =IFERROR('🏢 L1 Company OKRs'!Q16,"") -> 0 | K16: =IFERROR('🏢 L1 Company OKRs'!U16,"") -> 0
B17: L1 | C17: =IF('🏢 L1 Company OKRs'!C17="","",'🏢 L1 Company OKRs'!C17) | D17: =IF('🏢 L1 Company OKRs'!D17="","",'🏢 L1 Company OKRs'!D17) | E17: =IF('🏢 L1 Company OKRs'!E17="","",'🏢 L1 Company OKRs'!E17) | F17: =IFERROR('🏢 L1 Company OKRs'!J17,"") -> On Track KRs | G17: =IFERROR('🏢 L1 Company OKRs'!M17,"") -> 0 | H17: =IFERROR('🏢 L1 Company OKRs'!N17,"") -> Off Track KRs | I17: =IFERROR('🏢 L1 Company OKRs'!F17,"") -> Avg Google Score | J17: =IFERROR('🏢 L1 Company OKRs'!Q17,"") -> 0 | K17: =IFERROR('🏢 L1 Company OKRs'!U17,"") -> 0
B18: ▶ L2 — 🏬 L2 Dept OKRs
B19: L2 | C19: =IF('🏬 L2 Dept OKRs'!C5="","",'🏬 L2 Dept OKRs'!C5) -> Product: Deliver a 10/10 learning experience that HR professionals recommend unprompted | D19: =IF('🏬 L2 Dept OKRs'!D5="","",'🏬 L2 Dept OKRs'!D5) -> Reduce page load time to < 2s on all calculator pages | E19: =IF('🏬 L2 Dept OKRs'!E5="","",'🏬 L2 Dept OKRs'!E5) -> Head of Engineering | F19: =IFERROR('🏬 L2 Dept OKRs'!J5,"") -> 0 | G19: =IFERROR('🏬 L2 Dept OKRs'!M5,"") -> 0 | H19: =IFERROR('🏬 L2 Dept OKRs'!N5,"") -> 🔴 Off Track | I19: =IFERROR('🏬 L2 Dept OKRs'!F5,"") -> Committed | J19: =IFERROR('🏬 L2 Dept OKRs'!Q5,"") -> Q3 2026 | K19: =IFERROR('🏬 L2 Dept OKRs'!U5,"") -> Measure via Lighthouse
B20: L2 | C20: =IF('🏬 L2 Dept OKRs'!C6="","",'🏬 L2 Dept OKRs'!C6) | D20: =IF('🏬 L2 Dept OKRs'!D6="","",'🏬 L2 Dept OKRs'!D6) -> Ship Conversation Simulator v2 with lip-sync | E20: =IF('🏬 L2 Dept OKRs'!E6="","",'🏬 L2 Dept OKRs'!E6) -> Head of Product | F20: =IFERROR('🏬 L2 Dept OKRs'!J6,"") -> 0 | G20: =IFERROR('🏬 L2 Dept OKRs'!M6,"") -> 0 | H20: =IFERROR('🏬 L2 Dept OKRs'!N6,"") -> 🔴 Off Track | I20: =IFERROR('🏬 L2 Dept OKRs'!F6,"") -> Aspirational | J20: =IFERROR('🏬 L2 Dept OKRs'!Q6,"") -> Q3 2026 | K20: =IFERROR('🏬 L2 Dept OKRs'!U6,"") -> CSS lip overlay abandoned — real lip-sync needed
B21: L2 | C21: =IF('🏬 L2 Dept OKRs'!C7="","",'🏬 L2 Dept OKRs'!C7) | D21: =IF('🏬 L2 Dept OKRs'!D7="","",'🏬 L2 Dept OKRs'!D7) -> Publish 20 expert guides in Learning Hub | E21: =IF('🏬 L2 Dept OKRs'!E7="","",'🏬 L2 Dept OKRs'!E7) -> Head of Product | F21: =IFERROR('🏬 L2 Dept OKRs'!J7,"") -> 0.7 | G21: =IFERROR('🏬 L2 Dept OKRs'!M7,"") -> 70 | H21: =IFERROR('🏬 L2 Dept OKRs'!N7,"") -> 🟢 On Track | I21: =IFERROR('🏬 L2 Dept OKRs'!F7,"") -> Committed | J21: =IFERROR('🏬 L2 Dept OKRs'!Q7,"") -> Q3 2026 | K21: =IFERROR('🏬 L2 Dept OKRs'!U7,"") -> 14 live, 6 remaining
B22: L2 | C22: =IF('🏬 L2 Dept OKRs'!C8="","",'🏬 L2 Dept OKRs'!C8) | D22: =IF('🏬 L2 Dept OKRs'!D8="","",'🏬 L2 Dept OKRs'!D8) -> Achieve 4.5+ star avg on tool quality rating | E22: =IF('🏬 L2 Dept OKRs'!E8="","",'🏬 L2 Dept OKRs'!E8) -> CPO | F22: =IFERROR('🏬 L2 Dept OKRs'!J8,"") -> 0 | G22: =IFERROR('🏬 L2 Dept OKRs'!M8,"") -> 0 | H22: =IFERROR('🏬 L2 Dept OKRs'!N8,"") -> 🔴 Off Track | I22: =IFERROR('🏬 L2 Dept OKRs'!F8,"") -> Aspirational | J22: =IFERROR('🏬 L2 Dept OKRs'!Q8,"") -> Q3 2026 | K22: =IFERROR('🏬 L2 Dept OKRs'!U8,"") -> After beta launch
B23: L2 | C23: =IF('🏬 L2 Dept OKRs'!C9="","",'🏬 L2 Dept OKRs'!C9) -> Growth: Build a repeatable acquisition engine for HR professionals | D23: =IF('🏬 L2 Dept OKRs'!D9="","",'🏬 L2 Dept OKRs'!D9) -> Launch 15-post LinkedIn campaign on Day 1 of Gumroad activation | E23: =IF('🏬 L2 Dept OKRs'!E9="","",'🏬 L2 Dept OKRs'!E9) -> CMO | F23: =IFERROR('🏬 L2 Dept OKRs'!J9,"") -> 0 | G23: =IFERROR('🏬 L2 Dept OKRs'!M9,"") -> 0 | H23: =IFERROR('🏬 L2 Dept OKRs'!N9,"") -> 🔴 Off Track | I23: =IFERROR('🏬 L2 Dept OKRs'!F9,"") -> Committed | J23: =IFERROR('🏬 L2 Dept OKRs'!Q9,"") -> Q3 2026 | K23: =IFERROR('🏬 L2 Dept OKRs'!U9,"") -> Campaign written, not launched
B24: L2 | C24: =IF('🏬 L2 Dept OKRs'!C10="","",'🏬 L2 Dept OKRs'!C10) | D24: =IF('🏬 L2 Dept OKRs'!D10="","",'🏬 L2 Dept OKRs'!D10) -> Achieve 500 email signups in first 30 days post-launch | E24: =IF('🏬 L2 Dept OKRs'!E10="","",'🏬 L2 Dept OKRs'!E10) -> CMO | F24: =IFERROR('🏬 L2 Dept OKRs'!J10,"") -> 0 | G24: =IFERROR('🏬 L2 Dept OKRs'!M10,"") -> 0 | H24: =IFERROR('🏬 L2 Dept OKRs'!N10,"") -> 🔴 Off Track | I24: =IFERROR('🏬 L2 Dept OKRs'!F10,"") -> Aspirational | J24: =IFERROR('🏬 L2 Dept OKRs'!Q10,"") -> Q3 2026 | K24: =IFERROR('🏬 L2 Dept OKRs'!U10,"") -> After payments live
B25: L2 | C25: =IF('🏬 L2 Dept OKRs'!C11="","",'🏬 L2 Dept OKRs'!C11) | D25: =IF('🏬 L2 Dept OKRs'!D11="","",'🏬 L2 Dept OKRs'!D11) -> Get featured in 3 HR newsletters or communities | E25: =IF('🏬 L2 Dept OKRs'!E11="","",'🏬 L2 Dept OKRs'!E11) -> CMO | F25: =IFERROR('🏬 L2 Dept OKRs'!J11,"") -> 0 | G25: =IFERROR('🏬 L2 Dept OKRs'!M11,"") -> 0 | H25: =IFERROR('🏬 L2 Dept OKRs'!N11,"") -> 🔴 Off Track | I25: =IFERROR('🏬 L2 Dept OKRs'!F11,"") -> Aspirational | J25: =IFERROR('🏬 L2 Dept OKRs'!Q11,"") -> Q3 2026 | K25: =IFERROR('🏬 L2 Dept OKRs'!U11,"") -> Identify top 10 HR newsletters
B26: L2 | C26: =IF('🏬 L2 Dept OKRs'!C12="","",'🏬 L2 Dept OKRs'!C12) | D26: =IF('🏬 L2 Dept OKRs'!D12="","",'🏬 L2 Dept OKRs'!D12) -> Convert 10% of free users to Pro within 60 days | E26: =IF('🏬 L2 Dept OKRs'!E12="","",'🏬 L2 Dept OKRs'!E12) -> CMO | F26: =IFERROR('🏬 L2 Dept OKRs'!J12,"") -> 0 | G26: =IFERROR('🏬 L2 Dept OKRs'!M12,"") -> 0 | H26: =IFERROR('🏬 L2 Dept OKRs'!N12,"") -> 🔴 Off Track | I26: =IFERROR('🏬 L2 Dept OKRs'!F12,"") -> Aspirational | J26: =IFERROR('🏬 L2 Dept OKRs'!Q12,"") -> Q3 2026 | K26: =IFERROR('🏬 L2 Dept OKRs'!U12,"") -> GA4 goal setup needed
B27: L2 | C27: =IF('🏬 L2 Dept OKRs'!C13="","",'🏬 L2 Dept OKRs'!C13) -> People & Culture: Build a culture of learning and radical transparency | D27: =IF('🏬 L2 Dept OKRs'!D13="","",'🏬 L2 Dept OKRs'!D13) -> Complete all-hands OKR review every 2 weeks | E27: =IF('🏬 L2 Dept OKRs'!E13="","",'🏬 L2 Dept OKRs'!E13) -> CHRO | F27: =IFERROR('🏬 L2 Dept OKRs'!J13,"") -> 0 | G27: =IFERROR('🏬 L2 Dept OKRs'!M13,"") -> 0 | H27: =IFERROR('🏬 L2 Dept OKRs'!N13,"") -> 🔴 Off Track | I27: =IFERROR('🏬 L2 Dept OKRs'!F13,"") -> Committed | J27: =IFERROR('🏬 L2 Dept OKRs'!Q13,"") -> Q3 2026 | K27: =IFERROR('🏬 L2 Dept OKRs'!U13,"") -> 6 bi-weekly sessions per quarter
B28: L2 | C28: =IF('🏬 L2 Dept OKRs'!C14="","",'🏬 L2 Dept OKRs'!C14) | D28: =IF('🏬 L2 Dept OKRs'!D14="","",'🏬 L2 Dept OKRs'!D14) -> 100% of team has individual OKRs linked to company objectives | E28: =IF('🏬 L2 Dept OKRs'!E14="","",'🏬 L2 Dept OKRs'!E14) -> CHRO | F28: =IFERROR('🏬 L2 Dept OKRs'!J14,"") -> 0.6 | G28: =IFERROR('🏬 L2 Dept OKRs'!M14,"") -> 60 | H28: =IFERROR('🏬 L2 Dept OKRs'!N14,"") -> 🟡 At Risk | I28: =IFERROR('🏬 L2 Dept OKRs'!F14,"") -> Committed | J28: =IFERROR('🏬 L2 Dept OKRs'!Q14,"") -> Q3 2026 | K28: =IFERROR('🏬 L2 Dept OKRs'!U14,"") -> 60% done — L4 sheet in progress
B29: L2 | C29: =IF('🏬 L2 Dept OKRs'!C15="","",'🏬 L2 Dept OKRs'!C15) | D29: =IF('🏬 L2 Dept OKRs'!D15="","",'🏬 L2 Dept OKRs'!D15) -> Implement anonymous pulse survey with > 80% participation | E29: =IF('🏬 L2 Dept OKRs'!E15="","",'🏬 L2 Dept OKRs'!E15) -> CHRO | F29: =IFERROR('🏬 L2 Dept OKRs'!J15,"") -> 0 | G29: =IFERROR('🏬 L2 Dept OKRs'!M15,"") -> 0 | H29: =IFERROR('🏬 L2 Dept OKRs'!N15,"") -> 🔴 Off Track | I29: =IFERROR('🏬 L2 Dept OKRs'!F15,"") -> Aspirational | J29: =IFERROR('🏬 L2 Dept OKRs'!Q15,"") -> Q3 2026 | K29: =IFERROR('🏬 L2 Dept OKRs'!U15,"") -> Post-launch priority
B30: L2 | C30: =IF('🏬 L2 Dept OKRs'!C16="","",'🏬 L2 Dept OKRs'!C16) | D30: =IF('🏬 L2 Dept OKRs'!D16="","",'🏬 L2 Dept OKRs'!D16) | E30: =IF('🏬 L2 Dept OKRs'!E16="","",'🏬 L2 Dept OKRs'!E16) | F30: =IFERROR('🏬 L2 Dept OKRs'!J16,"") -> 0 | G30: =IFERROR('🏬 L2 Dept OKRs'!M16,"") -> 0 | H30: =IFERROR('🏬 L2 Dept OKRs'!N16,"") -> 0 | I30: =IFERROR('🏬 L2 Dept OKRs'!F16,"") -> 0 | J30: =IFERROR('🏬 L2 Dept OKRs'!Q16,"") -> 0 | K30: =IFERROR('🏬 L2 Dept OKRs'!U16,"") -> 0
B31: L2 | C31: =IF('🏬 L2 Dept OKRs'!C17="","",'🏬 L2 Dept OKRs'!C17) | D31: =IF('🏬 L2 Dept OKRs'!D17="","",'🏬 L2 Dept OKRs'!D17) | E31: =IF('🏬 L2 Dept OKRs'!E17="","",'🏬 L2 Dept OKRs'!E17) | F31: =IFERROR('🏬 L2 Dept OKRs'!J17,"") -> On Track KRs | G31: =IFERROR('🏬 L2 Dept OKRs'!M17,"") -> 1 | H31: =IFERROR('🏬 L2 Dept OKRs'!N17,"") -> Off Track KRs | I31: =IFERROR('🏬 L2 Dept OKRs'!F17,"") -> Avg Google Score | J31: =IFERROR('🏬 L2 Dept OKRs'!Q17,"") -> 0 | K31: =IFERROR('🏬 L2 Dept OKRs'!U17,"") -> 0
B32: ▶ L3 — 👥 L3 Team OKRs
B33: L3 | C33: =IF('👥 L3 Team OKRs'!C5="","",'👥 L3 Team OKRs'!C5) -> Engineering: Ship reliable, fast, delightful platform features every sprint | D33: =IF('👥 L3 Team OKRs'!D5="","",'👥 L3 Team OKRs'!D5) -> Zero critical bugs in production for 30 consecutive days | E33: =IF('👥 L3 Team OKRs'!E5="","",'👥 L3 Team OKRs'!E5) -> Tech Lead | F33: =IFERROR('👥 L3 Team OKRs'!J5,"") -> 0 | G33: =IFERROR('👥 L3 Team OKRs'!M5,"") -> 0 | H33: =IFERROR('👥 L3 Team OKRs'!N5,"") -> 🔴 Off Track | I33: =IFERROR('👥 L3 Team OKRs'!F5,"") -> Committed | J33: =IFERROR('👥 L3 Team OKRs'!Q5,"") -> Q3 2026 | K33: =IFERROR('👥 L3 Team OKRs'!U5,"") -> Track on Notion
B34: L3 | C34: =IF('👥 L3 Team OKRs'!C6="","",'👥 L3 Team OKRs'!C6) | D34: =IF('👥 L3 Team OKRs'!D6="","",'👥 L3 Team OKRs'!D6) -> Deploy PDF export to Goal Lab + Bias Audit | E34: =IF('👥 L3 Team OKRs'!E6="","",'👥 L3 Team OKRs'!E6) -> Tech Lead | F34: =IFERROR('👥 L3 Team OKRs'!J6,"") -> 1 | G34: =IFERROR('👥 L3 Team OKRs'!M6,"") -> 100 | H34: =IFERROR('👥 L3 Team OKRs'!N6,"") -> 🏆 Supercharged | I34: =IFERROR('👥 L3 Team OKRs'!F6,"") -> Committed | J34: =IFERROR('👥 L3 Team OKRs'!Q6,"") -> Q3 2026 | K34: =IFERROR('👥 L3 Team OKRs'!U6,"") -> Completed ✅
B35: L3 | C35: =IF('👥 L3 Team OKRs'!C7="","",'👥 L3 Team OKRs'!C7) | D35: =IF('👥 L3 Team OKRs'!D7="","",'👥 L3 Team OKRs'!D7) -> Implement 3D Talent Galaxy on landing page | E35: =IF('👥 L3 Team OKRs'!E7="","",'👥 L3 Team OKRs'!E7) -> Tech Lead | F35: =IFERROR('👥 L3 Team OKRs'!J7,"") -> 1 | G35: =IFERROR('👥 L3 Team OKRs'!M7,"") -> 100 | H35: =IFERROR('👥 L3 Team OKRs'!N7,"") -> 🏆 Supercharged | I35: =IFERROR('👥 L3 Team OKRs'!F7,"") -> Committed | J35: =IFERROR('👥 L3 Team OKRs'!Q7,"") -> Q3 2026 | K35: =IFERROR('👥 L3 Team OKRs'!U7,"") -> Completed ✅
